Workbook
Name Slicer_Product: #N/A
Name Slicer_Region: #N/A

Sheet RAW Data
A1: Date | B1: Order ID | C1: Product | D1: Region | E1: Sales Rep | F1: Units Sold | G1: Unit Price | H1: Total Sales
A2: Apr 28, 2025 | B2: ORD001 | C2: Laptop | D2: South | E2: Rohit | F2: 27 | G2: 1200 | H2: 32400
A3: 2025-04-08 | B3: ORD002 | C3: Accessories | D3: South | E3: Amit | F3: 30 | G3: 25000 | H3: 750000
A4: 2025-03-02 | B4: ORD003 | C4: Tablet | D4: South | E4: Sonia | F4: 23 | G4: 25000 | H4: 575000
A5: 2025-02-05 | B5: ORD004 | C5: Mobile | D5: North | E5: Neha | F5: 6 | G5: 800 | H5: 4800
A6: Feb 18, 2025 | B6: ORD005 | C6: Mobile | D6: East | E6: Riya | F6: 45 | G6: 30000 | H6: 1350000
A7: Feb 20, 2025 | B7: ORD006 | C7: Accessories | D7: North | E7: Karan | F7: 23 | G7: 1200 | H7: 27600
A8: Jun 06, 2025 | B8: ORD007 | C8: Tablet | D8: South | F8: 16 | G8: 800 | H8: 12800 | J8: =PROPER(TRIM(E8))
A9: 04/04/2025 | B9: ORD008 | C9: Mobile | D9: North | E9: Tina | F9: 50 | G9: 50000 | H9: 2500000
A10: 01/04/2025 | B10: ORD009 | C10: Accessories | D10: North | E10: Sonia | F10: 37 | G10: 15000 | H10: 555000
A11: 07/06/2025 | B11: ORD010 | C11: Laptop | D11: South | E11: Neha | F11: 40 | G11: 800 | H11: 32000
A12: Mar 15, 2025 | B12: ORD011 | C12: Mobile | D12: East | E12: Manish | F12: 41 | G12: 800 | H12: 32800
A13: Apr 25, 2025 | B13: ORD012 | C13: Accessories | D13: East | E13: Manish | F13: 27 | G13: 50000 | H13: 1350000
A14: 26/03/2025 | B14: ORD013 | C14: Accessories | D14: West | E14: Tina | F14: 32 | G14: 25000 | H14: 799549
A15: Feb 18, 2025 | B15: ORD014 | C15: Accessories | D15: North | E15: Tina | F15: 12 | G15: 30000 | H15: 360000
A16: May 31, 2025 | B16: ORD015 | C16: Laptop | D16: West | E16: Neha | F16: 26 | G16: 25000 | H16: 650000
A17: 2025-04-24 | B17: ORD016 | C17: Accessories | D17: East | E17: Priya | F17: 41 | G17: 50000 | H17: 2050000
A18: 08/01/2025 | B18: ORD017 | C18: Accessories | D18: West | E18: Tina | F18: 31 | G18: 1200 | H18: 37200
A19: 21/03/2025 | B19: ORD018 | C19: Mobile | D19: East | E19: Rohit | F19: 32 | G19: 1200 | H19: 38400
A20: 2025-03-13 | B20: ORD019 | C20: Accessories | D20: North | E20: Priya | F20: 24 | G20: 50000 | H20: 1200000
... A41: 12/05/2025 | B41: ORD040 | C41: Mobile | D41: West | E41: Neha | F41: 16 | G41: 50000 | H41: 800000
A42: 13/04/2025 | B42: ORD041 | C42: Laptop | D42: West | F42: 30 | G42: 800 | H42: 24000
A43: May 17, 2025 | B43: ORD042 | C43: Moblie | E43: Manish | F43: 3 | G43: 800 | H43: 2400
A44: 2025-02-24 | B44: ORD043 | C44: Laptop | D44: North | E44: Amit | F44: 40 | G44: 25000 | H44: 1000000
A45: 2025-03-11 | B45: ORD044 | C45: Mobile | D45: South | E45: Neha | F45: 7 | G45: 30000 | H45: 210000
A46: Jun 24, 2025 | B46: ORD045 | C46: Mobile | D46: East | E46: Riya | F46: 13 | G46: 30000 | H46: 390000
A47: 2025-02-17 | B47: ORD046 | C47: Mobile | D47: South | E47: Rohit | F47: 29 | G47: 1200 | H47: 34800
A48: 2025-01-20 | B48: ORD047 | C48: Laptop | D48: West | E48: Riya | F48: 45 | G48: 30000 | H48: 1350000
A49: 2025-06-04 | B49: ORD048 | C49: Laptop | D49: South | E49: Vivek | F49: 45 | G49: 15000 | H49: 675000
A50: 2025-03-16 | B50: ORD049 | C50: Accessories | D50: South | E50: Sonia | F50: 19 | G50: 800 | H50: 15200
A51: 2025-02-15 | B51: ORD050 | C51: Tablet | D51: West | E51: Rohit | F51: 47 | G51: 25000 | H51: 1175000
A52: 16/03/2025 | B52: ORD051 | C52: Mobile | D52: East | E52: Karan | F52: 10 | G52: 800 | H52: 7346
A53: 2025-06-07 | B53: ORD052 | C53: Laptop | E53: Amit | F53: 42 | G53: 15000 | H53: 630000
A54: 04/04/2025 | B54: ORD053 | C54: Mobile | D54: West | E54: Priya | F54: 19 | G54: 800 | H54: 15200
A55: 2025-01-29 | B55: ORD054 | C55: Accessories | F55: 49 | G55: 50000 | H55: 2450000
A56: 2025-06-11 | B56: ORD055 | C56: Lapotp | D56: East | E56: Rohit | F56: 14 | G56: 15000 | H56: 210000
A57: 2025-05-27 | B57: ORD056 | C57: Mobile | D57: West | E57: Sonia | F57: 10 | G57: 1200 | H57: 12000
A58: 18/03/2025 | B58: ORD057 | C58: Tablet | D58: North | E58: Sonia | F58: 24 | G58: 30000 | H58: 720000
A59: 2025-02-23 | B59: ORD058 | C59: Laptop | D59: West | E59: Sonia | F59: 23 | G59: 25000 | H59: 575000
A60: 2025-02-05 | B60: ORD059 | C60: Laptop | D60: West | E60: Vivek | F60: 7 | G60: 25000 | H60: 175000
...

Sheet Formatting
A1: Date Correction | E1: Proper & Trim | I1: Number Format | M1: Correct Formatted Table
A3: Date | B3: Checking format | C3: Date | E3: Product | F3: Region | G3: Sales Rep | I3: Units Sold | J3: Unit Price | K3: Total Sales | M3: Date | N3: Order ID | O3: Product | P3: Region | Q3: Sales Rep | R3: Units Sold | S3: Unit Price | T3: Total Sales
A4: Apr 28, 2025 | B4: =VALUE(A4) -> 45775 | C4: =IF(ISNUMBER(B4),B4,DATE(RIGHT(A4,4),MID(A4,4,2),LEFT(A4,2))) -> 45775 | E4: =PROPER(TRIM('RAW Data'!C2)) -> Laptop | F4: =PROPER(TRIM('RAW Data'!D2)) -> South | G4: =PROPER(TRIM('RAW Data'!E2)) -> Rohit | I4: 27 | J4: 1200 | K4: 32400 | M4: 45775 | N4: ORD001 | O4: Laptop | P4: South | Q4: Rohit | R4: 27 | S4: 1200 | T4: 32400
A5: 2025-04-08 | B5: =VALUE(A5) -> 45755 | C5: =IF(ISNUMBER(B5),B5,DATE(RIGHT(A5,4),MID(A5,4,2),LEFT(A5,2))) -> 45755 | E5: =PROPER(TRIM('RAW Data'!C3)) -> Accessories | F5: =PROPER(TRIM('RAW Data'!D3)) -> South | G5: =PROPER(TRIM('RAW Data'!E3)) -> Amit | I5: 30 | J5: 25000 | K5: 750000 | M5: 45755 | N5: ORD002 | O5: Accessories | P5: South | Q5: Amit | R5: 30 | S5: 25000 | T5: 750000
A6: 2025-03-02 | B6: =VALUE(A6) -> 45718 | C6: =IF(ISNUMBER(B6),B6,DATE(RIGHT(A6,4),MID(A6,4,2),LEFT(A6,2))) -> 45718 | E6: =PROPER(TRIM('RAW Data'!C4)) -> Tablet | F6: =PROPER(TRIM('RAW Data'!D4)) -> South | G6: =PROPER(TRIM('RAW Data'!E4)) -> Sonia | I6: 23 | J6: 25000 | K6: 575000 | M6: 45718 | N6: ORD003 | O6: Tablet | P6: South | Q6: Sonia | R6: 23 | S6: 25000 | T6: 575000
A7: 2025-02-05 | B7: =VALUE(A7) -> 45693 | C7: =IF(ISNUMBER(B7),B7,DATE(RIGHT(A7,4),MID(A7,4,2),LEFT(A7,2))) -> 45693 | E7: =PROPER(TRIM('RAW Data'!C5)) -> Mobile | F7: =PROPER(TRIM('RAW Data'!D5)) -> North | G7: =PROPER(TRIM('RAW Data'!E5)) -> Neha | I7: 6 | J7: 800 | K7: 4800 | M7: 45693 | N7: ORD004 | O7: Mobile | P7: North | Q7: Neha | R7: 6 | S7: 800 | T7: 4800
A8: Feb 18, 2025 | B8: =VALUE(A8) -> 45706 | C8: =IF(ISNUMBER(B8),B8,DATE(RIGHT(A8,4),MID(A8,4,2),LEFT(A8,2))) -> 45706 | E8: =PROPER(TRIM('RAW Data'!C6)) -> Mobile | F8: =PROPER(TRIM('RAW Data'!D6)) -> East | G8: =PROPER(TRIM('RAW Data'!E6)) -> Riya | I8: 45 | J8: 30000 | K8: 1350000 | M8: 45706 | N8: ORD005 | O8: Mobile | P8: East | Q8: Riya | R8: 45 | S8: 30000 | T8: 1350000
A9: Feb 20, 2025 | B9: =VALUE(A9) -> 45708 | C9: =IF(ISNUMBER(B9),B9,DATE(RIGHT(A9,4),MID(A9,4,2),LEFT(A9,2))) -> 45708 | E9: =PROPER(TRIM('RAW Data'!C7)) -> Accessories | F9: =PROPER(TRIM('RAW Data'!D7)) -> North | G9: =PROPER(TRIM('RAW Data'!E7)) -> Karan | I9: 23 | J9: 1200 | K9: 27600 | M9: 45708 | N9: ORD006 | O9: Accessories | P9: North | Q9: Karan | R9: 23 | S9: 1200 | T9: 27600
A10: Jun 06, 2025 | B10: =VALUE(A10) -> 45814 | C10: =IF(ISNUMBER(B10),B10,DATE(RIGHT(A10,4),MID(A10,4,2),LEFT(A10,2))) -> 45814 | E10: =PROPER(TRIM('RAW Data'!C8)) -> Tablet | F10: =PROPER(TRIM('RAW Data'!D8)) -> South | G10: =PROPER(TRIM('RAW Data'!E8)) | I10: 16 | J10: 800 | K10: 12800 | M10: 45814 | N10: ORD007 | O10: Tablet | P10: South | R10: 16 | S10: 800 | T10: 12800
A11: 04/04/2025 | B11: =VALUE(A11) -> 45751 | C11: =IF(ISNUMBER(B11),B11,DATE(RIGHT(A11,4),MID(A11,4,2),LEFT(A11,2))) -> 45751 | E11: =PROPER(TRIM('RAW Data'!C9)) -> Mobile | F11: =PROPER(TRIM('RAW Data'!D9)) -> North | G11: =PROPER(TRIM('RAW Data'!E9)) -> Tina | I11: 50 | J11: 50000 | K11: 2500000 | M11: 45751 | N11: ORD008 | O11: Mobile | P11: North | Q11: Tina | R11: 50 | S11: 50000 | T11: 2500000
A12: 01/04/2025 | B12: =VALUE(A12) -> 45661 | C12: =IF(ISNUMBER(B12),B12,DATE(RIGHT(A12,4),MID(A12,4,2),LEFT(A12,2))) -> 45661 | E12: =PROPER(TRIM('RAW Data'!C10)) -> Accessories | F12: =PROPER(TRIM('RAW Data'!D10)) -> North | G12: =PROPER(TRIM('RAW Data'!E10)) -> Sonia | I12: 37 | J12: 15000 | K12: 555000 | M12: 45661 | N12: ORD009 | O12: Accessories | P12: North | Q12: Sonia | R12: 37 | S12: 15000 | T12: 555000
A13: 07/06/2025 | B13: =VALUE(A13) -> 45844 | C13: =IF(ISNUMBER(B13),B13,DATE(RIGHT(A13,4),MID(A13,4,2),LEFT(A13,2))) -> 45844 | E13: =PROPER(TRIM('RAW Data'!C11)) -> Laptop | F13: =PROPER(TRIM('RAW Data'!D11)) -> South | G13: =PROPER(TRIM('RAW Data'!E11)) -> Neha | I13: 40 | J13: 800 | K13: 32000 | M13: 45844 | N13: ORD010 | O13: Laptop | P13: South | Q13: Neha | R13: 40 | S13: 800 | T13: 32000
A14: Mar 15, 2025 | B14: =VALUE(A14) -> 45731 | C14: =IF(ISNUMBER(B14),B14,DATE(RIGHT(A14,4),MID(A14,4,2),LEFT(A14,2))) -> 45731 | E14: =PROPER(TRIM('RAW Data'!C12)) -> Mobile | F14: =PROPER(TRIM('RAW Data'!D12)) -> East | G14: =PROPER(TRIM('RAW Data'!E12)) -> Manish | I14: 41 | J14: 800 | K14: 32800 | M14: 45731 | N14: ORD011 | O14: Mobile | P14: East | Q14: Manish | R14: 41 | S14: 800 | T14: 32800
A15: Apr 25, 2025 | B15: =VALUE(A15) -> 45772 | C15: =IF(ISNUMBER(B15),B15,DATE(RIGHT(A15,4),MID(A15,4,2),LEFT(A15,2))) -> 45772 | E15: =PROPER(TRIM('RAW Data'!C13)) -> Accessories | F15: =PROPER(TRIM('RAW Data'!D13)) -> East | G15: =PROPER(TRIM('RAW Data'!E13)) -> Manish | I15: 27 | J15: 50000 | K15: 1350000 | M15: 45772 | N15: ORD012 | O15: Accessories | P15: East | Q15: Manish | R15: 27 | S15: 50000 | T15: 1350000
A16: 26/03/2025 | B16: =VALUE(A16) -> #VALUE! | C16: =IF(ISNUMBER(B16),B16,DATE(RIGHT(A16,4),MID(A16,4,2),LEFT(A16,2))) -> 45742 | E16: =PROPER(TRIM('RAW Data'!C14)) -> Accessories | F16: =PROPER(TRIM('RAW Data'!D14)) -> West | G16: =PROPER(TRIM('RAW Data'!E14)) -> Tina | I16: 32 | J16: 25000 | K16: 799549 | M16: 45742 | N16: ORD013 | O16: Accessories | P16: West | Q16: Tina | R16: 32 | S16: 25000 | T16: 799549
A17: Feb 18, 2025 | B17: =VALUE(A17) -> 45706 | C17: =IF(ISNUMBER(B17),B17,DATE(RIGHT(A17,4),MID(A17,4,2),LEFT(A17,2))) -> 45706 | E17: =PROPER(TRIM('RAW Data'!C15)) -> Accessories | F17: =PROPER(TRIM('RAW Data'!D15)) -> North | G17: =PROPER(TRIM('RAW Data'!E15)) -> Tina | I17: 12 | J17: 30000 | K17: 360000 | M17: 45706 | N17: ORD014 | O17: Accessories | P17: North | Q17: Tina | R17: 12 | S17: 30000 | T17: 360000
A18: May 31, 2025 | B18: =VALUE(A18) -> 45808 | C18: =IF(ISNUMBER(B18),B18,DATE(RIGHT(A18,4),MID(A18,4,2),LEFT(A18,2))) -> 45808 | E18: =PROPER(TRIM('RAW Data'!C16)) -> Laptop | F18: =PROPER(TRIM('RAW Data'!D16)) -> West | G18: =PROPER(TRIM('RAW Data'!E16)) -> Neha | I18: 26 | J18: 25000 | K18: 650000 | M18: 45808 | N18: ORD015 | O18: Laptop | P18: West | Q18: Neha | R18: 26 | S18: 25000 | T18: 650000
A19: 2025-04-24 | B19: =VALUE(A19) -> 45771 | C19: =IF(ISNUMBER(B19),B19,DATE(RIGHT(A19,4),MID(A19,4,2),LEFT(A19,2))) -> 45771 | E19: =PROPER(TRIM('RAW Data'!C17)) -> Accessories | F19: =PROPER(TRIM('RAW Data'!D17)) -> East | G19: =PROPER(TRIM('RAW Data'!E17)) -> Priya | I19: 41 | J19: 50000 | K19: 2050000 | M19: 45771 | N19: ORD016 | O19: Accessories | P19: East | Q19: Priya | R19: 41 | S19: 50000 | T19: 2050000
A20: 08/01/2025 | B20: =VALUE(A20) -> 45870 | C20: =IF(ISNUMBER(B20),B20,DATE(RIGHT(A20,4),MID(A20,4,2),LEFT(A20,2))) -> 45870 | E20: =PROPER(TRIM('RAW Data'!C18)) -> Accessories | F20: =PROPER(TRIM('RAW Data'!D18)) -> West | G20: =PROPER(TRIM('RAW Data'!E18)) -> Tina | I20: 31 | J20: 1200 | K20: 37200 | M20: 45870 | N20: ORD017 | O20: Accessories | P20: West | Q20: Tina | R20: 31 | S20: 1200 | T20: 37200
A21: 21/03/2025 | B21: =VALUE(A21) -> #VALUE! | C21: =IF(ISNUMBER(B21),B21,DATE(RIGHT(A21,4),MID(A21,4,2),LEFT(A21,2))) -> 45737 | E21: =PROPER(TRIM('RAW Data'!C19)) -> Mobile | F21: =PROPER(TRIM('RAW Data'!D19)) -> East | G21: =PROPER(TRIM('RAW Data'!E19)) -> Rohit | I21: 32 | J21: 1200 | K21: 38400 | M21: 45737 | N21: ORD018 | O21: Mobile | P21: East | Q21: Rohit | R21: 32 | S21: 1200 | T21: 38400
A22: 2025-03-13 | B22: =VALUE(A22) -> 45729 | C22: =IF(ISNUMBER(B22),B22,DATE(RIGHT(A22,4),MID(A22,4,2),LEFT(A22,2))) -> 45729 | E22: =PROPER(TRIM('RAW Data'!C20)) -> Accessories | F22: =PROPER(TRIM('RAW Data'!D20)) -> North | G22: =PROPER(TRIM('RAW Data'!E20)) -> Priya | I22: 24 | J22: 50000 | K22: 1200000 | M22: 45729 | N22: ORD019 | O22: Accessories | P22: North | Q22: Priya | R22: 24 | S22: 50000 | T22: 1200000
... A43: 12/05/2025 | B43: =VALUE(A43) -> 45996 | C43: =IF(ISNUMBER(B43),B43,DATE(RIGHT(A43,4),MID(A43,4,2),LEFT(A43,2))) -> 45996 | E43: =PROPER(TRIM('RAW Data'!C41)) -> Mobile | F43: =PROPER(TRIM('RAW Data'!D41)) -> West | G43: =PROPER(TRIM('RAW Data'!E41)) -> Neha | I43: 16 | J43: 50000 | K43: 800000 | M43: 45996 | N43: ORD040 | O43: Mobile | P43: West | Q43: Neha | R43: 16 | S43: 50000 | T43: 800000
A44: 13/04/2025 | B44: =VALUE(A44) -> #VALUE! | C44: =IF(ISNUMBER(B44),B44,DATE(RIGHT(A44,4),MID(A44,4,2),LEFT(A44,2))) -> 45760 | E44: =PROPER(TRIM('RAW Data'!C42)) -> Laptop | F44: =PROPER(TRIM('RAW Data'!D42)) -> West | G44: =PROPER(TRIM('RAW Data'!E42)) | I44: 30 | J44: 800 | K44: 24000 | M44: 45760 | N44: ORD041 | O44: Laptop | P44: West | R44: 30 | S44: 800 | T44: 24000
A45: May 17, 2025 | B45: =VALUE(A45) -> 45794 | C45: =IF(ISNUMBER(B45),B45,DATE(RIGHT(A45,4),MID(A45,4,2),LEFT(A45,2))) -> 45794 | E45: =PROPER(TRIM('RAW Data'!C43)) -> Moblie | F45: =PROPER(TRIM('RAW Data'!D43)) | G45: =PROPER(TRIM('RAW Data'!E43)) -> Manish | I45: 3 | J45: 800 | K45: 2400 | M45: 45794 | N45: ORD042 | O45: Moblie | Q45: Manish | R45: 3 | S45: 800 | T45: 2400
A46: 2025-02-24 | B46: =VALUE(A46) -> 45712 | C46: =IF(ISNUMBER(B46),B46,DATE(RIGHT(A46,4),MID(A46,4,2),LEFT(A46,2))) -> 45712 | E46: =PROPER(TRIM('RAW Data'!C44)) -> Laptop | F46: =PROPER(TRIM('RAW Data'!D44)) -> North | G46: =PROPER(TRIM('RAW Data'!E44)) -> Amit | I46: 40 | J46: 25000 | K46: 1000000 | M46: 45712 | N46: ORD043 | O46: Laptop | P46: North | Q46: Amit | R46: 40 | S46: 25000 | T46: 1000000
A47: 2025-03-11 | B47: =VALUE(A47) -> 45727 | C47: =IF(ISNUMBER(B47),B47,DATE(RIGHT(A47,4),MID(A47,4,2),LEFT(A47,2))) -> 45727 | E47: =PROPER(TRIM('RAW Data'!C45)) -> Mobile | F47: =PROPER(TRIM('RAW Data'!D45)) -> South | G47: =PROPER(TRIM('RAW Data'!E45)) -> Neha | I47: 7 | J47: 30000 | K47: 210000 | M47: 45727 | N47: ORD044 | O47: Mobile | P47: South | Q47: Neha | R47: 7 | S47: 30000 | T47: 210000
A48: Jun 24, 2025 | B48: =VALUE(A48) -> 45832 | C48: =IF(ISNUMBER(B48),B48,DATE(RIGHT(A48,4),MID(A48,4,2),LEFT(A48,2))) -> 45832 | E48: =PROPER(TRIM('RAW Data'!C46)) -> Mobile | F48: =PROPER(TRIM('RAW Data'!D46)) -> East | G48: =PROPER(TRIM('RAW Data'!E46)) -> Riya | I48: 13 | J48: 30000 | K48: 390000 | M48: 45832 | N48: ORD045 | O48: Mobile | P48: East | Q48: Riya | R48: 13 | S48: 30000 | T48: 390000
A49: 2025-02-17 | B49: =VALUE(A49) -> 45705 | C49: =IF(ISNUMBER(B49),B49,DATE(RIGHT(A49,4),MID(A49,4,2),LEFT(A49,2))) -> 45705 | E49: =PROPER(TRIM('RAW Data'!C47)) -> Mobile | F49: =PROPER(TRIM('RAW Data'!D47)) -> South | G49: =PROPER(TRIM('RAW Data'!E47)) -> Rohit | I49: 29 | J49: 1200 | K49: 34800 | M49: 45705 | N49: ORD046 | O49: Mobile | P49: South | Q49: Rohit | R49: 29 | S49: 1200 | T49: 34800
A50: 2025-01-20 | B50: =VALUE(A50) -> 45677 | C50: =IF(ISNUMBER(B50),B50,DATE(RIGHT(A50,4),MID(A50,4,2),LEFT(A50,2))) -> 45677 | E50: =PROPER(TRIM('RAW Data'!C48)) -> Laptop | F50: =PROPER(TRIM('RAW Data'!D48)) -> West | G50: =PROPER(TRIM('RAW Data'!E48)) -> Riya | I50: 45 | J50: 30000 | K50: 1350000 | M50: 45677 | N50: ORD047 | O50: Laptop | P50: West | Q50: Riya | R50: 45 | S50: 30000 | T50: 1350000
A51: 2025-06-04 | B51: =VALUE(A51) -> 45812 | C51: =IF(ISNUMBER(B51),B51,DATE(RIGHT(A51,4),MID(A51,4,2),LEFT(A51,2))) -> 45812 | E51: =PROPER(TRIM('RAW Data'!C49)) -> Laptop | F51: =PROPER(TRIM('RAW Data'!D49)) -> South | G51: =PROPER(TRIM('RAW Data'!E49)) -> Vivek | I51: 45 | J51: 15000 | K51: 675000 | M51: 45812 | N51: ORD048 | O51: Laptop | P51: South | Q51: Vivek | R51: 45 | S51: 15000 | T51: 675000
A52: 2025-03-16 | B52: =VALUE(A52) -> 45732 | C52: =IF(ISNUMBER(B52),B52,DATE(RIGHT(A52,4),MID(A52,4,2),LEFT(A52,2))) -> 45732 | E52: =PROPER(TRIM('RAW Data'!C50)) -> Accessories | F52: =PROPER(TRIM('RAW Data'!D50)) -> South | G52: =PROPER(TRIM('RAW Data'!E50)) -> Sonia | I52: 19 | J52: 800 | K52: 15200 | M52: 45732 | N52: ORD049 | O52: Accessories | P52: South | Q52: Sonia | R52: 19 | S52: 800 | T52: 15200
A53: 2025-02-15 | B53: =VALUE(A53) -> 45703 | C53: =IF(ISNUMBER(B53),B53,DATE(RIGHT(A53,4),MID(A53,4,2),LEFT(A53,2))) -> 45703 | E53: =PROPER(TRIM('RAW Data'!C51)) -> Tablet | F53: =PROPER(TRIM('RAW Data'!D51)) -> West | G53: =PROPER(TRIM('RAW Data'!E51)) -> Rohit | I53: 47 | J53: 25000 | K53: 1175000 | M53: 45703 | N53: ORD050 | O53: Tablet | P53: West | Q53: Rohit | R53: 47 | S53: 25000 | T53: 1175000
A54: 16/03/2025 | B54: =VALUE(A54) -> #VALUE! | C54: =IF(ISNUMBER(B54),B54,DATE(RIGHT(A54,4),MID(A54,4,2),LEFT(A54,2))) -> 45732 | E54: =PROPER(TRIM('RAW Data'!C52)) -> Mobile | F54: =PROPER(TRIM('RAW Data'!D52)) -> East | G54: =PROPER(TRIM('RAW Data'!E52)) -> Karan | I54: 10 | J54: 800 | K54: 7346 | M54: 45732 | N54: ORD051 | O54: Mobile | P54: East | Q54: Karan | R54: 10 | S54: 800 | T54: 7346
A55: 2025-06-07 | B55: =VALUE(A55) -> 45815 | C55: =IF(ISNUMBER(B55),B55,DATE(RIGHT(A55,4),MID(A55,4,2),LEFT(A55,2))) -> 45815 | E55: =PROPER(TRIM('RAW Data'!C53)) -> Laptop | F55: =PROPER(TRIM('RAW Data'!D53)) | G55: =PROPER(TRIM('RAW Data'!E53)) -> Amit | I55: 42 | J55: 15000 | K55: 630000 | M55: 45815 | N55: ORD052 | O55: Laptop | Q55: Amit | R55: 42 | S55: 15000 | T55: 630000
A56: 04/04/2025 | B56: =VALUE(A56) -> 45751 | C56: =IF(ISNUMBER(B56),B56,DATE(RIGHT(A56,4),MID(A56,4,2),LEFT(A56,2))) -> 45751 | E56: =PROPER(TRIM('RAW Data'!C54)) -> Mobile | F56: =PROPER(TRIM('RAW Data'!D54)) -> West | G56: =PROPER(TRIM('RAW Data'!E54)) -> Priya | I56: 19 | J56: 800 | K56: 15200 | M56: 45751 | N56: ORD053 | O56: Mobile | P56: West | Q56: Priya | R56: 19 | S56: 800 | T56: 15200
A57: 2025-01-29 | B57: =VALUE(A57) -> 45686 | C57: =IF(ISNUMBER(B57),B57,DATE(RIGHT(A57,4),MID(A57,4,2),LEFT(A57,2))) -> 45686 | E57: =PROPER(TRIM('RAW Data'!C55)) -> Accessories | F57: =PROPER(TRIM('RAW Data'!D55)) | G57: =PROPER(TRIM('RAW Data'!E55)) | I57: 49 | J57: 50000 | K57: 2450000 | M57: 45686 | N57: ORD054 | O57: Accessories | R57: 49 | S57: 50000 | T57: 2450000
A58: 2025-06-11 | B58: =VALUE(A58) -> 45819 | C58: =IF(ISNUMBER(B58),B58,DATE(RIGHT(A58,4),MID(A58,4,2),LEFT(A58,2))) -> 45819 | E58: =PROPER(TRIM('RAW Data'!C56)) -> Lapotp | F58: =PROPER(TRIM('RAW Data'!D56)) -> East | G58: =PROPER(TRIM('RAW Data'!E56)) -> Rohit | I58: 14 | J58: 15000 | K58: 210000 | M58: 45819 | N58: ORD055 | O58: Lapotp | P58: East | Q58: Rohit | R58: 14 | S58: 15000 | T58: 210000
A59: 2025-05-27 | B59: =VALUE(A59) -> 45804 | C59: =IF(ISNUMBER(B59),B59,DATE(RIGHT(A59,4),MID(A59,4,2),LEFT(A59,2))) -> 45804 | E59: =PROPER(TRIM('RAW Data'!C57)) -> Mobile | F59: =PROPER(TRIM('RAW Data'!D57)) -> West | G59: =PROPER(TRIM('RAW Data'!E57)) -> Sonia | I59: 10 | J59: 1200 | K59: 12000 | M59: 45804 | N59: ORD056 | O59: Mobile | P59: West | Q59: Sonia | R59: 10 | S59: 1200 | T59: 12000
A60: 18/03/2025 | B60: =VALUE(A60) -> #VALUE! | C60: =IF(ISNUMBER(B60),B60,DATE(RIGHT(A60,4),MID(A60,4,2),LEFT(A60,2))) -> 45734 | E60: =PROPER(TRIM('RAW Data'!C58)) -> Tablet | F60: =PROPER(TRIM('RAW Data'!D58)) -> North | G60: =PROPER(TRIM('RAW Data'!E58)) -> Sonia | I60: 24 | J60: 30000 | K60: 720000 | M60: 45734 | N60: ORD057 | O60: Tablet | P60: North | Q60: Sonia | R60: 24 | S60: 30000 | T60: 720000
A61: 2025-02-23 | B61: =VALUE(A61) -> 45711 | C61: =IF(ISNUMBER(B61),B61,DATE(RIGHT(A61,4),MID(A61,4,2),LEFT(A61,2))) -> 45711 | E61: =PROPER(TRIM('RAW Data'!C59)) -> Laptop | F61: =PROPER(TRIM('RAW Data'!D59)) -> West | G61: =PROPER(TRIM('RAW Data'!E59)) -> Sonia | I61: 23 | J61: 25000 | K61: 575000 | M61: 45711 | N61: ORD058 | O61: Laptop | P61: West | Q61: Sonia | R61: 23 | S61: 25000 | T61: 575000
...

Sheet Missing Values
A1: Contains Missing Values | I1: Fixing Missing Values
P2: Most Frequent Region | S2: Person with most saler per Region
A3: Date | B3: Order ID | C3: Product | D3: Region | E3: Sales Rep | F3: Units Sold | G3: Unit Price | H3: Total Sales | I3: Missing Region | J3: Corrected Region | K3: Missing Sales Rep | L3: Corrected Sales Rep
A4: 45775 | B4: ORD001 | C4: Laptop | D4: South | E4: Rohit | F4: 27 | G4: 1200 | H4: 32400 | I4: =IF(D4="",$P$5,"") | J4: =IF(I4="",D4,I4) -> South | K4: {=_xlfn.IFS(AND(J4=$S$6,E4=""),$T$6,AND(J4=$S$17,E4=""),$T$17,AND(J4=$S$29,E4=""),$T$29,AND(J4=$S$41,E4=""),$T$41,TRUE,"")} | L4: =IF(K4="",E4,K4) -> Rohit | P4: Region | Q4: Count of Region | S4: Region | T4: Sales Rep | U4: Count of Sales Rep
A5: 45755 | B5: ORD002 | C5: Accessories | D5: South | E5: Amit | F5: 30 | G5: 25000 | H5: 750000 | I5: =IF(D5="",$P$5,"") | J5: =IF(I5="",D5,I5) -> South | K5: {=_xlfn.IFS(AND(J5=$S$6,E5=""),$T$6,AND(J5=$S$17,E5=""),$T$17,AND(J5=$S$29,E5=""),$T$29,AND(J5=$S$41,E5=""),$T$41,TRUE,"")} | L5: =IF(K5="",E5,K5) -> Amit | P5: South | Q5: 52 | U5: 9
A6: 45718 | B6: ORD003 | C6: Tablet | D6: South | E6: Sonia | F6: 23 | G6: 25000 | H6: 575000 | I6: =IF(D6="",$P$5,"") | J6: =IF(I6="",D6,I6) -> South | K6: {=_xlfn.IFS(AND(J6=$S$6,E6=""),$T$6,AND(J6=$S$17,E6=""),$T$17,AND(J6=$S$29,E6=""),$T$29,AND(J6=$S$41,E6=""),$T$41,TRUE,"")} | L6: =IF(K6="",E6,K6) -> Sonia | P6: East | Q6: 50 | S6: East | T6: Tina | U6: 10
A7: 45693 | B7: ORD004 | C7: Mobile | D7: North | E7: Neha | F7: 6 | G7: 800 | H7: 4800 | I7: =IF(D7="",$P$5,"") | J7: =IF(I7="",D7,I7) -> North | K7: {=_xlfn.IFS(AND(J7=$S$6,E7=""),$T$6,AND(J7=$S$17,E7=""),$T$17,AND(J7=$S$29,E7=""),$T$29,AND(J7=$S$41,E7=""),$T$41,TRUE,"")} | L7: =IF(K7="",E7,K7) -> Neha | P7: North | Q7: 45 | T7: Manish | U7: 6
A8: 45706 | B8: ORD005 | C8: Mobile | D8: East | E8: Riya | F8: 45 | G8: 30000 | H8: 1350000 | I8: =IF(D8="",$P$5,"") | J8: =IF(I8="",D8,I8) -> East | K8: {=_xlfn.IFS(AND(J8=$S$6,E8=""),$T$6,AND(J8=$S$17,E8=""),$T$17,AND(J8=$S$29,E8=""),$T$29,AND(J8=$S$41,E8=""),$T$41,TRUE,"")} | L8: =IF(K8="",E8,K8) -> Riya | P8: West | Q8: 44 | T8: Priya | U8: 6
A9: 45708 | B9: ORD006 | C9: Accessories | D9: North | E9: Karan | F9: 23 | G9: 1200 | H9: 27600 | I9: =IF(D9="",$P$5,"") | J9: =IF(I9="",D9,I9) -> North | K9: {=_xlfn.IFS(AND(J9=$S$6,E9=""),$T$6,AND(J9=$S$17,E9=""),$T$17,AND(J9=$S$29,E9=""),$T$29,AND(J9=$S$41,E9=""),$T$41,TRUE,"")} | L9: =IF(K9="",E9,K9) -> Karan | Q9: 9 | T9: Amit | U9: 5
A10: 45814 | B10: ORD007 | C10: Tablet | D10: South | F10: 16 | G10: 800 | H10: 12800 | I10: =IF(D10="",$P$5,"") | J10: =IF(I10="",D10,I10) -> South | K10: {=_xlfn.IFS(AND(J10=$S$6,E10=""),$T$6,AND(J10=$S$17,E10=""),$T$17,AND(J10=$S$29,E10=""),$T$29,AND(J10=$S$41,E10=""),$T$41,TRUE,"")} -> Sonia | L10: =IF(K10="",E10,K10) -> Sonia | P10: Grand Total | Q10: 200 | T10: Karan | U10: 5
A11: 45751 | B11: ORD008 | C11: Mobile | D11: North | E11: Tina | F11: 50 | G11: 50000 | H11: 2500000 | I11: =IF(D11="",$P$5,"") | J11: =IF(I11="",D11,I11) -> North | K11: {=_xlfn.IFS(AND(J11=$S$6,E11=""),$T$6,AND(J11=$S$17,E11=""),$T$17,AND(J11=$S$29,E11=""),$T$29,AND(J11=$S$41,E11=""),$T$41,TRUE,"")} | L11: =IF(K11="",E11,K11) -> Tina | T11: Rohit | U11: 5
A12: 45661 | B12: ORD009 | C12: Accessories | D12: North | E12: Sonia | F12: 37 | G12: 15000 | H12: 555000 | I12: =IF(D12="",$P$5,"") | J12: =IF(I12="",D12,I12) -> North | K12: {=_xlfn.IFS(AND(J12=$S$6,E12=""),$T$6,AND(J12=$S$17,E12=""),$T$17,AND(J12=$S$29,E12=""),$T$29,AND(J12=$S$41,E12=""),$T$41,TRUE,"")} | L12: =IF(K12="",E12,K12) -> Sonia | T12: Riya | U12: 4
A13: 45844 | B13: ORD010 | C13: Laptop | D13: South | E13: Neha | F13: 40 | G13: 800 | H13: 32000 | I13: =IF(D13="",$P$5,"") | J13: =IF(I13="",D13,I13) -> South | K13: {=_xlfn.IFS(AND(J13=$S$6,E13=""),$T$6,AND(J13=$S$17,E13=""),$T$17,AND(J13=$S$29,E13=""),$T$29,AND(J13=$S$41,E13=""),$T$41,TRUE,"")} | L13: =IF(K13="",E13,K13) -> Neha | T13: Sonia | U13: 4
A14: 45731 | B14: ORD011 | C14: Mobile | D14: East | E14: Manish | F14: 41 | G14: 800 | H14: 32800 | I14: =IF(D14="",$P$5,"") | J14: =IF(I14="",D14,I14) -> East | K14: {=_xlfn.IFS(AND(J14=$S$6,E14=""),$T$6,AND(J14=$S$17,E14=""),$T$17,AND(J14=$S$29,E14=""),$T$29,AND(J14=$S$41,E14=""),$T$41,TRUE,"")} | L14: =IF(K14="",E14,K14) -> Manish | T14: Neha | U14: 3
A15: 45772 | B15: ORD012 | C15: Accessories | D15: East | E15: Manish | F15: 27 | G15: 50000 | H15: 1350000 | I15: =IF(D15="",$P$5,"") | J15: =IF(I15="",D15,I15) -> East | K15: {=_xlfn.IFS(AND(J15=$S$6,E15=""),$T$6,AND(J15=$S$17,E15=""),$T$17,AND(J15=$S$29,E15=""),$T$29,AND(J15=$S$41,E15=""),$T$41,TRUE,"")} | L15: =IF(K15="",E15,K15) -> Manish | T15: Vivek | U15: 2
A16: 45742 | B16: ORD013 | C16: Accessories | D16: West | E16: Tina | F16: 32 | G16: 25000 | H16: 799549 | I16: =IF(D16="",$P$5,"") | J16: =IF(I16="",D16,I16) -> West | K16: {=_xlfn.IFS(AND(J16=$S$6,E16=""),$T$6,AND(J16=$S$17,E16=""),$T$17,AND(J16=$S$29,E16=""),$T$29,AND(J16=$S$41,E16=""),$T$41,TRUE,"")} | L16: =IF(K16="",E16,K16) -> Tina | S16: East Total | U16: 50
A17: 45706 | B17: ORD014 | C17: Accessories | D17: North | E17: Tina | F17: 12 | G17: 30000 | H17: 360000 | I17: =IF(D17="",$P$5,"") | J17: =IF(I17="",D17,I17) -> North | K17: {=_xlfn.IFS(AND(J17=$S$6,E17=""),$T$6,AND(J17=$S$17,E17=""),$T$17,AND(J17=$S$29,E17=""),$T$29,AND(J17=$S$41,E17=""),$T$41,TRUE,"")} | L17: =IF(K17="",E17,K17) -> Tina | S17: North | T17: Tina | U17: 9
A18: 45808 | B18: ORD015 | C18: Laptop | D18: West | E18: Neha | F18: 26 | G18: 25000 | H18: 650000 | I18: =IF(D18="",$P$5,"") | J18: =IF(I18="",D18,I18) -> West | K18: {=_xlfn.IFS(AND(J18=$S$6,E18=""),$T$6,AND(J18=$S$17,E18=""),$T$17,AND(J18=$S$29,E18=""),$T$29,AND(J18=$S$41,E18=""),$T$41,TRUE,"")} | L18: =IF(K18="",E18,K18) -> Neha | T18: Riya | U18: 7
A19: 45771 | B19: ORD016 | C19: Accessories | D19: East | E19: Priya | F19: 41 | G19: 50000 | H19: 2050000 | I19: =IF(D19="",$P$5,"") | J19: =IF(I19="",D19,I19) -> East | K19: {=_xlfn.IFS(AND(J19=$S$6,E19=""),$T$6,AND(J19=$S$17,E19=""),$T$17,AND(J19=$S$29,E19=""),$T$29,AND(J19=$S$41,E19=""),$T$41,TRUE,"")} | L19: =IF(K19="",E19,K19) -> Priya | T19: Rohit | U19: 5
A20: 45870 | B20: ORD017 | C20: Accessories | D20: West | E20: Tina | F20: 31 | G20: 1200 | H20: 37200 | I20: =IF(D20="",$P$5,"") | J20: =IF(I20="",D20,I20) -> West | K20: {=_xlfn.IFS(AND(J20=$S$6,E20=""),$T$6,AND(J20=$S$17,E20=""),$T$17,AND(J20=$S$29,E20=""),$T$29,AND(J20=$S$41,E20=""),$T$41,TRUE,"")} | L20: =IF(K20="",E20,K20) -> Tina | T20: Sonia | U20: 5
A21: 45737 | B21: ORD018 | C21: Mobile | D21: East | E21: Rohit | F21: 32 | G21: 1200 | H21: 38400 | I21: =IF(D21="",$P$5,"") | J21: =IF(I21="",D21,I21) -> East | K21: {=_xlfn.IFS(AND(J21=$S$6,E21=""),$T$6,AND(J21=$S$17,E21=""),$T$17,AND(J21=$S$29,E21=""),$T$29,AND(J21=$S$41,E21=""),$T$41,TRUE,"")} | L21: =IF(K21="",E21,K21) -> Rohit | T21: Karan | U21: 5
A22: 45729 | B22: ORD019 | C22: Accessories | D22: North | E22: Priya | F22: 24 | G22: 50000 | H22: 1200000 | I22: =IF(D22="",$P$5,"") | J22: =IF(I22="",D22,I22) -> North | K22: {=_xlfn.IFS(AND(J22=$S$6,E22=""),$T$6,AND(J22=$S$17,E22=""),$T$17,AND(J22=$S$29,E22=""),$T$29,AND(J22=$S$41,E22=""),$T$41,TRUE,"")} | L22: =IF(K22="",E22,K22) -> Priya | T22: Amit | U22: 4
A23: 45801 | B23: ORD020 | C23: Tablet | D23: East | E23: Neha | F23: 31 | G23: 50000 | H23: 1550000 | I23: =IF(D23="",$P$5,"") | J23: =IF(I23="",D23,I23) -> East | K23: {=_xlfn.IFS(AND(J23=$S$6,E23=""),$T$6,AND(J23=$S$17,E23=""),$T$17,AND(J23=$S$29,E23=""),$T$29,AND(J23=$S$41,E23=""),$T$41,TRUE,"")} | L23: =IF(K23="",E23,K23) -> Neha | T23: Priya | U23: 4
A24: 45817 | B24: ORD021 | C24: Accessories | D24: South | E24: Vivek | F24: 7 | G24: 15000 | H24: 105000 | I24: =IF(D24="",$P$5,"") | J24: =IF(I24="",D24,I24) -> South | K24: {=_xlfn.IFS(AND(J24=$S$6,E24=""),$T$6,AND(J24=$S$17,E24=""),$T$17,AND(J24=$S$29,E24=""),$T$29,AND(J24=$S$41,E24=""),$T$41,TRUE,"")} | L24: =IF(K24="",E24,K24) -> Vivek | T24: Vivek | U24: 2
A25: 45824 | B25: ORD022 | C25: Accessories | D25: East | E25: Neha | F25: 35 | G25: 800 | H25: 28000 | I25: =IF(D25="",$P$5,"") | J25: =IF(I25="",D25,I25) -> East | K25: {=_xlfn.IFS(AND(J25=$S$6,E25=""),$T$6,AND(J25=$S$17,E25=""),$T$17,AND(J25=$S$29,E25=""),$T$29,AND(J25=$S$41,E25=""),$T$41,TRUE,"")} | L25: =IF(K25="",E25,K25) -> Neha | T25: Manish | U25: 2
A26: 45827 | B26: ORD023 | C26: Tablet | D26: West | E26: Tina | F26: 18 | G26: 1200 | H26: 21600 | I26: =IF(D26="",$P$5,"") | J26: =IF(I26="",D26,I26) -> West | K26: {=_xlfn.IFS(AND(J26=$S$6,E26=""),$T$6,AND(J26=$S$17,E26=""),$T$17,AND(J26=$S$29,E26=""),$T$29,AND(J26=$S$41,E26=""),$T$41,TRUE,"")} | L26: =IF(K26="",E26,K26) -> Tina | T26: Neha | U26: 1
A27: 45697 | B27: ORD024 | C27: Mobile | D27: West | E27: Tina | F27: 45 | G27: 25000 | H27: 1125000 | I27: =IF(D27="",$P$5,"") | J27: =IF(I27="",D27,I27) -> West | K27: {=_xlfn.IFS(AND(J27=$S$6,E27=""),$T$6,AND(J27=$S$17,E27=""),$T$17,AND(J27=$S$29,E27=""),$T$29,AND(J27=$S$41,E27=""),$T$41,TRUE,"")} | L27: =IF(K27="",E27,K27) -> Tina | U27: 1
A28: 45676 | B28: ORD025 | C28: Laptop | D28: South | E28: Priya | F28: 20 | G28: 800 | H28: 16000 | I28: =IF(D28="",$P$5,"") | J28: =IF(I28="",D28,I28) -> South | K28: {=_xlfn.IFS(AND(J28=$S$6,E28=""),$T$6,AND(J28=$S$17,E28=""),$T$17,AND(J28=$S$29,E28=""),$T$29,AND(J28=$S$41,E28=""),$T$41,TRUE,"")} | L28: =IF(K28="",E28,K28) -> Priya | S28: North Total | U28: 45
A29: 45726 | B29: ORD026 | C29: Tablet | D29: East | E29: Amit | F29: 30 | G29: 25000 | H29: 750000 | I29: =IF(D29="",$P$5,"") | J29: =IF(I29="",D29,I29) -> East | K29: {=_xlfn.IFS(AND(J29=$S$6,E29=""),$T$6,AND(J29=$S$17,E29=""),$T$17,AND(J29=$S$29,E29=""),$T$29,AND(J29=$S$41,E29=""),$T$41,TRUE,"")} | L29: =IF(K29="",E29,K29) -> Amit | S29: South | T29: Sonia | U29: 9
A30: 45820 | B30: ORD027 | C30: Laptop | D30: South | E30: Vivek | F30: 4 | G30: 25000 | H30: 100000 | I30: =IF(D30="",$P$5,"") | J30: =IF(I30="",D30,I30) -> South | K30: {=_xlfn.IFS(AND(J30=$S$6,E30=""),$T$6,AND(J30=$S$17,E30=""),$T$17,AND(J30=$S$29,E30=""),$T$29,AND(J30=$S$41,E30=""),$T$41,TRUE,"")} | L30: =IF(K30="",E30,K30) -> Vivek | T30: Vivek | U30: 8
A31: 45683 | B31: ORD028 | C31: Tablet | D31: East | E31: Tina | F31: 37 | G31: 50000 | H31: 1850000 | I31: =IF(D31="",$P$5,"") | J31: =IF(I31="",D31,I31) -> East | K31: {=_xlfn.IFS(AND(J31=$S$6,E31=""),$T$6,AND(J31=$S$17,E31=""),$T$17,AND(J31=$S$29,E31=""),$T$29,AND(J31=$S$41,E31=""),$T$41,TRUE,"")} | L31: =IF(K31="",E31,K31) -> Tina | T31: Riya | U31: 6
A32: 45837 | B32: ORD029 | C32: Mobile | D32: North | E32: Amit | F32: 13 | G32: 30000 | H32: 390000 | I32: =IF(D32="",$P$5,"") | J32: =IF(I32="",D32,I32) -> North | K32: {=_xlfn.IFS(AND(J32=$S$6,E32=""),$T$6,AND(J32=$S$17,E32=""),$T$17,AND(J32=$S$29,E32=""),$T$29,AND(J32=$S$41,E32=""),$T$41,TRUE,"")} | L32: =IF(K32="",E32,K32) -> Amit | T32: Neha | U32: 6
A33: 45834 | B33: ORD030 | C33: Mobile | D33: North | E33: Sonia | F33: 23 | G33: 1200 | H33: 27600 | I33: =IF(D33="",$P$5,"") | J33: =IF(I33="",D33,I33) -> North | K33: {=_xlfn.IFS(AND(J33=$S$6,E33=""),$T$6,AND(J33=$S$17,E33=""),$T$17,AND(J33=$S$29,E33=""),$T$29,AND(J33=$S$41,E33=""),$T$41,TRUE,"")} | L33: =IF(K33="",E33,K33) -> Sonia | T33: Priya | U33: 6
A34: 45803 | B34: ORD031 | C34: Tablet | D34: North | E34: Riya | F34: 31 | G34: 50000 | H34: 1550000 | I34: =IF(D34="",$P$5,"") | J34: =IF(I34="",D34,I34) -> North | K34: {=_xlfn.IFS(AND(J34=$S$6,E34=""),$T$6,AND(J34=$S$17,E34=""),$T$17,AND(J34=$S$29,E34=""),$T$29,AND(J34=$S$41,E34=""),$T$41,TRUE,"")} | L34: =IF(K34="",E34,K34) -> Riya | T34: Manish | U34: 5
A35: 45789 | B35: ORD032 | C35: Laptop | D35: South | E35: Vivek | F35: 24 | G35: 25000 | H35: 600000 | I35: =IF(D35="",$P$5,"") | J35: =IF(I35="",D35,I35) -> South | K35: {=_xlfn.IFS(AND(J35=$S$6,E35=""),$T$6,AND(J35=$S$17,E35=""),$T$17,AND(J35=$S$29,E35=""),$T$29,AND(J35=$S$41,E35=""),$T$41,TRUE,"")} | L35: =IF(K35="",E35,K35) -> Vivek | T35: Amit | U35: 4
A36: 45825 | B36: ORD033 | C36: Accessories | D36: South | E36: Karan | F36: 32 | G36: 25000 | H36: 800000 | I36: =IF(D36="",$P$5,"") | J36: =IF(I36="",D36,I36) -> South | K36: {=_xlfn.IFS(AND(J36=$S$6,E36=""),$T$6,AND(J36=$S$17,E36=""),$T$17,AND(J36=$S$29,E36=""),$T$29,AND(J36=$S$41,E36=""),$T$41,TRUE,"")} | L36: =IF(K36="",E36,K36) -> Karan | T36: Rohit | U36: 3
A37: 45810 | B37: ORD034 | C37: Tablet | D37: South | E37: Vivek | F37: 21 | G37: 15000 | H37: 315000 | I37: =IF(D37="",$P$5,"") | J37: =IF(I37="",D37,I37) -> South | K37: {=_xlfn.IFS(AND(J37=$S$6,E37=""),$T$6,AND(J37=$S$17,E37=""),$T$17,AND(J37=$S$29,E37=""),$T$29,AND(J37=$S$41,E37=""),$T$41,TRUE,"")} | L37: =IF(K37="",E37,K37) -> Vivek | T37: Karan | U37: 2
A38: 45768 | B38: ORD035 | C38: Accessories | D38: East | E38: Karan | F38: 49 | G38: 1200 | H38: 58800 | I38: =IF(D38="",$P$5,"") | J38: =IF(I38="",D38,I38) -> East | K38: {=_xlfn.IFS(AND(J38=$S$6,E38=""),$T$6,AND(J38=$S$17,E38=""),$T$17,AND(J38=$S$29,E38=""),$T$29,AND(J38=$S$41,E38=""),$T$41,TRUE,"")} | L38: =IF(K38="",E38,K38) -> Karan | U38: 2
A39: 45680 | B39: ORD036 | C39: Laptop | D39: North | E39: Manish | F39: 10 | G39: 15000 | H39: 150000 | I39: =IF(D39="",$P$5,"") | J39: =IF(I39="",D39,I39) -> North | K39: {=_xlfn.IFS(AND(J39=$S$6,E39=""),$T$6,AND(J39=$S$17,E39=""),$T$17,AND(J39=$S$29,E39=""),$T$29,AND(J39=$S$41,E39=""),$T$41,TRUE,"")} | L39: =IF(K39="",E39,K39) -> Manish | T39: Tina | U39: 1
A40: 45780 | B40: ORD037 | C40: Accessories | D40: North | E40: Riya | F40: 43 | G40: 50000 | H40: 2150000 | I40: =IF(D40="",$P$5,"") | J40: =IF(I40="",D40,I40) -> North | K40: {=_xlfn.IFS(AND(J40=$S$6,E40=""),$T$6,AND(J40=$S$17,E40=""),$T$17,AND(J40=$S$29,E40=""),$T$29,AND(J40=$S$41,E40=""),$T$41,TRUE,"")} | L40: =IF(K40="",E40,K40) -> Riya | S40: South Total | U40: 52
...

Sheet Mis-spellings
A1: Table | J1: Spelling Mistakes | M1: Helper Column
A2: Date | B2: Order ID | C2: Product | D2: Corrected Region | E2: Corrected Sales Rep | F2: Units Sold | G2: Unit Price | H2: Total Sales | J2: Mistakes | K2: Corrected | M2: {=_xlfn.UNIQUE(C3:C202)} -> Laptop | N2: Laptop
A3: 45775 | B3: ORD001 | C3: Laptop | D3: South | E3: Rohit | F3: 27 | G3: 1200 | H3: 32400 | J3: Laptop | K3: {=_xlfn.XLOOKUP(C3,_xlfn.ANCHORARRAY($M$2),$N$2:$N$9)} -> Laptop | M3: Accessories | N3: Accessories
A4: 45755 | B4: ORD002 | C4: Accessories | D4: South | E4: Amit | F4: 30 | G4: 25000 | H4: 750000 | J4: Accessories | K4: {=_xlfn.XLOOKUP(C4,_xlfn.ANCHORARRAY($M$2),$N$2:$N$9)} -> Accessories | M4: Tabllet | N4: Tablet
A5: 45718 | B5: ORD003 | C5: Tabllet | D5: South | E5: Sonia | F5: 23 | G5: 25000 | H5: 575000 | J5: Tabllet | K5: {=_xlfn.XLOOKUP(C5,_xlfn.ANCHORARRAY($M$2),$N$2:$N$9)} -> Tablet | M5: Mobile | N5: Mobile
A6: 45693 | B6: ORD004 | C6: Mobile | D6: North | E6: Neha | F6: 6 | G6: 800 | H6: 4800 | J6: Mobile | K6: {=_xlfn.XLOOKUP(C6,_xlfn.ANCHORARRAY($M$2),$N$2:$N$9)} -> Mobile | M6: Tablet | N6: Tablet
A7: 45706 | B7: ORD005 | C7: Mobile | D7: East | E7: Riya | F7: 45 | G7: 30000 | H7: 1350000 | J7: Mobile | K7: {=_xlfn.XLOOKUP(C7,_xlfn.ANCHORARRAY($M$2),$N$2:$N$9)} -> Mobile | M7: Moblie | N7: Mobile
A8: 45708 | B8: ORD006 | C8: Accessories | D8: North | E8: Karan | F8: 23 | G8: 1200 | H8: 27600 | J8: Accessories | K8: {=_xlfn.XLOOKUP(C8,_xlfn.ANCHORARRAY($M$2),$N$2:$N$9)} -> Accessories | M8: Lapotp | N8: Laptop
A9: 45814 | B9: ORD007 | C9: Tablet | D9: South | E9: Sonia | F9: 16 | G9: 800 | H9: 12800 | J9: Tablet | K9: {=_xlfn.XLOOKUP(C9,_xlfn.ANCHORARRAY($M$2),$N$2:$N$9)} -> Tablet | M9: Accesories | N9: Accessories
A10: 45751 | B10: ORD008 | C10: Mobile | D10: North | E10: Tina | F10: 50 | G10: 50000 | H10: 2500000 | J10: Mobile | K10: {=_xlfn.XLOOKUP(C10,_xlfn.ANCHORARRAY($M$2),$N$2:$N$9)} -> Mobile
A11: 45661 | B11: ORD009 | C11: Accessories | D11: North | E11: Sonia | F11: 37 | G11: 15000 | H11: 555000 | J11: Accessories | K11: {=_xlfn.XLOOKUP(C11,_xlfn.ANCHORARRAY($M$2),$N$2:$N$9)} -> Accessories
A12: 45844 | B12: ORD010 | C12: Laptop | D12: South | E12: Neha | F12: 40 | G12: 800 | H12: 32000 | J12: Laptop | K12: {=_xlfn.XLOOKUP(C12,_xlfn.ANCHORARRAY($M$2),$N$2:$N$9)} -> Laptop
A13: 45731 | B13: ORD011 | C13: Mobile | D13: East | E13: Manish | F13: 41 | G13: 800 | H13: 32800 | J13: Mobile | K13: {=_xlfn.XLOOKUP(C13,_xlfn.ANCHORARRAY($M$2),$N$2:$N$9)} -> Mobile
A14: 45772 | B14: ORD012 | C14: Accessories | D14: East | E14: Manish | F14: 27 | G14: 50000 | H14: 1350000 | J14: Accessories | K14: {=_xlfn.XLOOKUP(C14,_xlfn.ANCHORARRAY($M$2),$N$2:$N$9)} -> Accessories
A15: 45742 | B15: ORD013 | C15: Accessories | D15: West | E15: Tina | F15: 32 | G15: 25000 | H15: 799549 | J15: Accessories | K15: {=_xlfn.XLOOKUP(C15,_xlfn.ANCHORARRAY($M$2),$N$2:$N$9)} -> Accessories
A16: 45706 | B16: ORD014 | C16: Accessories | D16: North | E16: Tina | F16: 12 | G16: 30000 | H16: 360000 | J16: Accessories | K16: {=_xlfn.XLOOKUP(C16,_xlfn.ANCHORARRAY($M$2),$N$2:$N$9)} -> Accessories
A17: 45808 | B17: ORD015 | C17: Laptop | D17: West | E17: Neha | F17: 26 | G17: 25000 | H17: 650000 | J17: Laptop | K17: {=_xlfn.XLOOKUP(C17,_xlfn.ANCHORARRAY($M$2),$N$2:$N$9)} -> Laptop
A18: 45771 | B18: ORD016 | C18: Accessories | D18: East | E18: Priya | F18: 41 | G18: 50000 | H18: 2050000 | J18: Accessories | K18: {=_xlfn.XLOOKUP(C18,_xlfn.ANCHORARRAY($M$2),$N$2:$N$9)} -> Accessories
A19: 45870 | B19: ORD017 | C19: Accessories | D19: West | E19: Tina | F19: 31 | G19: 1200 | H19: 37200 | J19: Accessories | K19: {=_xlfn.XLOOKUP(C19,_xlfn.ANCHORARRAY($M$2),$N$2:$N$9)} -> Accessories
A20: 45737 | B20: ORD018 | C20: Mobile | D20: East | E20: Rohit | F20: 32 | G20: 1200 | H20: 38400 | J20: Mobile | K20: {=_xlfn.XLOOKUP(C20,_xlfn.ANCHORARRAY($M$2),$N$2:$N$9)} -> Mobile
A21: 45729 | B21: ORD019 | C21: Accessories | D21: North | E21: Priya | F21: 24 | G21: 50000 | H21: 1200000 | J21: Accessories | K21: {=_xlfn.XLOOKUP(C21,_xlfn.ANCHORARRAY($M$2),$N$2:$N$9)} -> Accessories
... A202: 45772 | B202: ORD200 | C202: Tablet | D202: North | E202: Sonia | F202: 46 | G202: 25000 | H202: 1150000 | J202: Tablet | K202: {=_xlfn.XLOOKUP(C202,_xlfn.ANCHORARRAY($M$2),$N$2:$N$9)} -> Tablet

Sheet Corrected Table
A1: Fully Corrected Table
A3: Date | B3: Order ID | C3: Product | D3: Region | E3: Sales-Person | F3: Units Sold | G3: Unit Price | H3: Total Sales
A4: 45775 | B4: ORD001 | C4: Laptop | D4: South | E4: Rohit | F4: 27 | G4: 1200 | H4: 32400
A5: 45755 | B5: ORD002 | C5: Accessories | D5: South | E5: Amit | F5: 30 | G5: 25000 | H5: 750000
A6: 45718 | B6: ORD003 | C6: Tablet | D6: South | E6: Sonia | F6: 23 | G6: 25000 | H6: 575000
A7: 45693 | B7: ORD004 | C7: Mobile | D7: North | E7: Neha | F7: 6 | G7: 800 | H7: 4800
A8: 45706 | B8: ORD005 | C8: Mobile | D8: East | E8: Riya | F8: 45 | G8: 30000 | H8: 1350000
A9: 45708 | B9: ORD006 | C9: Accessories | D9: North | E9: Karan | F9: 23 | G9: 1200 | H9: 27600
A10: 45814 | B10: ORD007 | C10: Tablet | D10: South | E10: Sonia | F10: 16 | G10: 800 | H10: 12800
A11: 45751 | B11: ORD008 | C11: Mobile | D11: North | E11: Tina | F11: 50 | G11: 50000 | H11: 2500000
A12: 45661 | B12: ORD009 | C12: Accessories | D12: North | E12: Sonia | F12: 37 | G12: 15000 | H12: 555000
A13: 45844 | B13: ORD010 | C13: Laptop | D13: South | E13: Neha | F13: 40 | G13: 800 | H13: 32000
A14: 45731 | B14: ORD011 | C14: Mobile | D14: East | E14: Manish | F14: 41 | G14: 800 | H14: 32800
A15: 45772 | B15: ORD012 | C15: Accessories | D15: East | E15: Manish | F15: 27 | G15: 50000 | H15: 1350000
... A203: 45772 | B203: ORD200 | C203: Tablet | D203: North | E203: Sonia | F203: 46 | G203: 25000 | H203: 1150000

Sheet Dashboard
A1: DASHBOARD
G4: REGION
C9: Total sales | F9: Top Product | H9: Top Sales-person | K9: Top Sales Month
C10: =D18 -> 109347886 | F10: =B14 -> Accessories | H10: =F14 -> Sonia | K10: =TEXT(K14,"MMMM") -> September
B13: Product | C13: Sum of Units Sold | D13: Sum of Total Sales | F13: Sales-Person | G13: Sum of Units Sold | H13: Sum of Total Sales | I13: Product | K13: Date | L13: Sum of Total Sales
B14: Accessories | C14: 1508 | D14: 39832090 | F14: Sonia | G14: 916 | H14: 22821350 | K14: 45901 | L14: 3094958
B15: Tablet | C15: 1161 | D15: 25853147 | F15: Tina | G15: 834 | H15: 18153649 | K15: 45703 | L15: 3065000
B16: Mobile | C16: 1225 | D16: 24246811 | F16: Riya | G16: 544 | H16: 15433301 | K16: 45780 | L16: 3045400
B17: Laptop | C17: 1163 | D17: 19415838 | F17: Amit | G17: 526 | H17: 11186200 | K17: 45742 | L17: 2849549
B18: Grand Total | C18: 5057 | D18: 109347886 | F18: Karan | G18: 495 | H18: 9969546 | K18: 45701 | L18: 2825000
F19: Priya | G19: 376 | H19: 11544600
